<?xml version="1.0" encoding="utf-8"?>
<robot
  name="Printed Articulated Robotic Arm(new version)">
  <link
    name="base_link">
    <inertial>
      <origin
        xyz="0 0 0"
        rpy="0 0 0" />
      <mass
        value="6.75668097016176" />
      <inertia
        ixx="0.0599282179819153"
        ixy="-0.000130355139638627"
        ixz="0.000148566526141822"
        iyy="0.0576079890426347"
        iyz="-0.000103369122242167"
        izz="0.113155928677968" />
    </inertial>
    <visual>
      <origin
        xyz="0 0 0"
        rpy="0 0 0" />
      <geometry>
        <mesh
          filename="meshes/base_link.STL" />
      </geometry>
      <material
        name="">
        <color
          rgba="0.752941176470588 0.752941176470588 0.752941176470588 1" />
      </material>
    </visual>
  </link>
  <link
    name="alpha_link">
    <inertial>
      <origin
        xyz="0 0 0"
        rpy="0 0 0" />
      <mass
        value="5.16328117790804" />
      <inertia
        ixx="0.013734956330358"
        ixy="2.02538455830793E-07"
        ixz="1.37404309702668E-07"
        iyy="0.0127550401310653"
        iyz="-0.000733419497812231"
        izz="0.013411256517451" />
    </inertial>
    <visual>
      <origin
        xyz="0 0 0"
        rpy="0 0 0" />
      <geometry>
        <mesh
          filename="meshes/alpha_link.STL" />
      </geometry>
      <material
        name="">
        <color
          rgba="0.752941176470588 0.752941176470588 0.752941176470588 1" />
      </material>
    </visual>
  </link>
  <joint
    name="base_alpha_joint"
    type="continuous">
    <origin
      xyz="0 0 .2351278"
      rpy="0 0 0" />
    <parent
      link="base_link" />
    <child
      link="alpha_link" />
    <axis
      xyz="0 0 1" />

  </joint>
  <link
    name="beta_link">
    <inertial>
      <origin
        xyz="0 0 0"
        rpy="0 0 0" />
      <mass
        value="2.08470844237959" />
      <inertia
        ixx="0.00727313166572859"
        ixy="6.36014654470775E-06"
        ixz="1.37342312383256E-06"
        iyy="0.00430805438604519"
        iyz="3.02777003405499E-06"
        izz="0.00830103377862874" />
    </inertial>
    <visual>
      <origin
        xyz="0 0 0"
        rpy="0 0 0" />
      <geometry>
        <mesh
          filename="meshes/beta_link.STL" />
      </geometry>
      <material
        name="">
        <color
          rgba="0.752941176470588 0.752941176470588 0.752941176470588 1" />
      </material>
    </visual>
  </link>
  <joint
    name="alpha_beta_joint"
    type="continuous">
    <origin
      xyz="0 0 .2234041"
      rpy="-1.5707 0 0" />
    <parent
      link="alpha_link" />
    <child
      link="beta_link" />
    <axis
      xyz="1 0 0" />
    <limit
      lower="-0.436"
      upper="1.571"
      effort="0"
      velocity="0" />
  </joint>
  <link
    name="gamma_link">
    <inertial>
      <origin
        xyz="0 0 0"
        rpy="0 0 0" />
      <mass
        value="0.815696288881645" />
      <inertia
        ixx="0.00360508959996844"
        ixy="5.72341440191991E-11"
        ixz="1.2580308769082E-08"
        iyy="0.00179141230717756"
        iyz="2.53493713742895E-09"
        izz="0.00432497826164946" />
    </inertial>
    <visual>
      <origin
        xyz="0 0 0"
        rpy="0 0 0" />
      <geometry>
        <mesh
          filename="meshes/gamma_link.STL" />
      </geometry>
      <material
        name="">
        <color
          rgba="0.752941176470588 0.752941176470588 0.752941176470588 1" />
      </material>
    </visual>
  </link>
  <joint
    name="beta_gamma_joint"
    type="continuous">
    <origin
      xyz="0 0 .47625"
      rpy="0 0 0" />
    <parent
      link="beta_link" />
    <child
      link="gamma_link" />
    <axis
      xyz="1 0 0" />
    <limit
      lower="-1.75"
      upper="1.047"
      effort="0"
      velocity="0" />
  </joint>
  <link
    name="end_effector">
    <inertial>
      <origin
        xyz="0 0 0"
        rpy="0 0 3.1415" />
      <mass
        value="0.46171251803447" />
      <inertia
        ixx="0.000553762624711399"
        ixy="3.24725925538111E-11"
        ixz="6.79420736251352E-11"
        iyy="0.000457848188914449"
        iyz="4.39900148911372E-06"
        izz="0.000545934362303271" />
    </inertial>
    <visual>
      <origin
        xyz="0 0 0"
        rpy="0 0 3.1415" />
      <geometry>
        <mesh
          filename="meshes/end_effector.STL" />
      </geometry>
      <material
        name="">
        <color
          rgba="0.752941176470588 0.752941176470588 0.752941176470588 1" />
      </material>
    </visual>
  </link>
  <joint
    name="gamma_ee_joint"
    type="fixed">
    <origin
      xyz="0 0 .46355"
      rpy="0 0 0" />
    <parent
      link="gamma_link" />
    <child
      link="end_effector" />
    <axis
      xyz="0 0 0" />
  </joint>
  <link
    name="end_effector_tip">
    <inertial>
      <origin
        xyz="0 0 0"
        rpy="0 0 0" />
      <mass
        value="0.46171251803447" />
      <inertia
        ixx="0.000553762624711399"
        ixy="3.24725925538111E-11"
        ixz="6.79420736251352E-11"
        iyy="0.000457848188914449"
        iyz="4.39900148911372E-06"
        izz="0.000545934362303271" />
    </inertial>
    <visual>
      <origin
        xyz="0 0 0"
        rpy="0 0 0" />
      <geometry>
        <mesh filename="textured_sphere_smooth.obj" scale="0.005 0.005 0.005"/>
      </geometry>
      <material
        name="">
        <color
          rgba="0.752941176470588 0.752941176470588 0.752941176470588 1" />
      </material>
    </visual>
  </link>
  <joint
    name="ee_ee_tip_joint"
    type="fixed">
    <origin
      xyz="0 .0889 .04859"
      rpy="0 0 0" />
    <parent
      link="end_effector" />
    <child
      link="end_effector_tip" />
    <axis
      xyz="0 0 0" />
  </joint>
</robot>
